<?xml version='1.0'?>
<sdf version='1.7'>
    <model name='amp'>


        <link name='base_link'>
        <inertial>
        <pose>-0.032 0 0.070 0 0 1.5708</pose>
        <inertia>
          <!-- <ixx>7.2397393e-01</ixx>
          <ixy>4.686399e-10</ixy>
          <ixz>-1.09525703e-08</ixz>
          <iyy>7.2397393e-01</iyy>
          <iyz>2.8582649e-09</iyz>
          <izz>6.53050163e-01</izz> -->
        </inertia>
        <mass>60.2573504</mass>
      </inertial>
         <pose>0.003725 0.051897 0.100757 0 -0 1.5708</pose>
          <visual name='base_visual'>
            <geometry>
            <pose>0 0 0 0 0 1.5708</pose>
              <mesh>
                <uri>model://amp_hull/amp_hull.obj</uri>
                <scale>1 1.2 1</scale>
              </mesh>
            </geometry>
          </visual>
          <collision name='base_collision'>
            <geometry>
              <mesh>
                <uri>model://amp_hull/amp_hull.obj</uri>
              </mesh>
            </geometry>
          </collision>

        </link>



        <link name='front_axle_link'>
         <pose>-0.000953 0.793081 -0.001476 0 0 0</pose>
         <inertial>
        <pose>0 0 0 0 0 0</pose>
        <inertia>
          <!-- <ixx>7.2397393e-01</ixx>
          <ixy>4.686399e-10</ixy>
          <ixz>-1.09525703e-08</ixz>
          <iyy>7.2397393e-01</iyy>
          <iyz>2.8582649e-09</iyz>
          <izz>6.53050163e-01</izz> -->
        </inertia>
        <mass>4.2573504</mass>
      </inertial>
          <visual name='front_axle_visual'>
            <geometry>
              <mesh>
                <uri>model://amp_axle/amp_axle.obj</uri>
                <scale>1.2 1 1</scale>

              </mesh>
            </geometry>
            <material>
        <ambient>0.2 0.2 0.2 1</ambient>
        <diffuse>0.8 0.8 0.8 1</diffuse>
        <specular>0.2 0.2 0.2 1</specular>
        <emissive>0 0 0 1</emissive>
      </material>
          </visual>
          <collision name='front_axle_collision'>
          <pose>0 0 0 0 0 1.5708</pose>
            <geometry>
              <mesh>
                <uri>model://amp_axle/axle_new.obj</uri>
                <scale>1 1.08 1</scale>
              </mesh>

            </geometry>
            <surface>
        <friction>
          <ode>
            <mu>0.9</mu>
            <mu2>0.9</mu2>
          </ode>
        </friction>
      </surface>

          </collision>
      <!-- <collision name="axle_collision">
        <geometry>
          <cylinder>
            <radius>0.1</radius>
            <length>1.2</length>
          </cylinder>
        </geometry>
        <pose>0 0 0 0 1.5708 0</pose>
      </collision> -->
      <!-- <collision name="wheel_left_collision">
        <pose>-0.6 0 0 0 1.72 0</pose>
        <geometry>
          <cylinder>
            <radius>0.18</radius>
            <length>0.2</length>
          </cylinder>
        </geometry>
      </collision>
      <collision name="wheel_right_collision">
        <pose>0.6 0 0 0 1.42 0</pose>
        <geometry>
          <cylinder>
            <radius>0.18</radius>
            <length>0.2</length>
          </cylinder>
        </geometry>
      </collision> -->
        </link>

        <link name="front_swivel_link">
  <pose>-0.000953 0.793081 -0.001476 0 0 0</pose>
  <inertial>
    <mass>1.0</mass>
    <pose>0 0 0 0 0 0</pose>
    <inertia>
      <ixx>0.001</ixx>
      <iyy>0.001</iyy>
      <izz>0.001</izz>
    </inertia>
  </inertial>
  <visual name="front_swivel">
    <geometry>
      <box>
        <size>0.1 0.1 0.1</size>
      </box>
    </geometry>
  </visual>
</link>





        <link name='back_axle_link'>
         <pose>-0.002768 -0.844977 0.000719 0 0 0</pose>
         <inertial>
        <pose>0 0 0 0 0 0</pose>
        <inertia>
          <!-- <ixx>7.2397393e-01</ixx>
          <ixy>4.686399e-10</ixy>
          <ixz>-1.09525703e-08</ixz>
          <iyy>7.2397393e-01</iyy>
          <iyz>2.8582649e-09</iyz>
          <izz>6.53050163e-01</izz> -->
        </inertia>
        <mass>4.2573504</mass>
      </inertial>
          <visual name='back_axle_visual'>
            <geometry>
              <mesh>
                <uri>model://amp_axle/amp_axle.obj</uri>
                <scale>1.2 1 1</scale>
                
              </mesh>
            </geometry>
            <material>
        <ambient>0.2 0.2 0.2 1</ambient>
        <diffuse>0.8 0.8 0.8 1</diffuse>
        <specular>0.2 0.2 0.2 1</specular>
        <emissive>0 0 0 1</emissive>
      </material>
          </visual>
          <collision name='back_axle_collision'>
          <pose>0 0 0 0 0 1.5708</pose>
            <geometry>
              <mesh>
                <uri>model://amp_axle/axle_new.obj</uri>
                <scale>1 1.08 1</scale>
              </mesh>
            </geometry>

            <surface>
        <friction>
          <ode>
            <mu>0.9</mu>
            <mu2>0.9</mu2>
          </ode>
        </friction>
        </surface>
            
          </collision>

          <!-- <collision name="axle_collision">
        <geometry>
          <cylinder>
            <radius>0.1</radius>
            <length>1.2</length>
          </cylinder>
        </geometry>
        <pose>0 0 0 0 1.5708 0</pose>
      </collision> -->
      <!-- <collision name="wheel_left_collision">
        <pose>-0.6 0 0 0 1.72 0</pose>
        <geometry>
          <cylinder>
            <radius>0.18</radius>
            <length>0.2</length>
          </cylinder>
        </geometry>
      </collision>
      <collision name="wheel_right_collision">
        <pose>0.6 0 0 0 1.42 0</pose>
        <geometry>
          <cylinder>
            <radius>0.18</radius>
            <length>0.2</length>
          </cylinder>
        </geometry>
      </collision> -->
        </link>

<link name="back_swivel_link">
  <pose>-0.002768 -0.844977 0.000719 0 0 0</pose>
  <inertial>
    <mass>1.0</mass>
    <pose>0 0 0 0 0 0</pose>
    <inertia>
      <ixx>0.001</ixx>
      <iyy>0.001</iyy>
      <izz>0.001</izz>
    </inertia>
  </inertial>
  <visual name="back_swivel">
    <geometry>
      <box>
        <size>0.1 0.1 0.1</size>
      </box>
    </geometry>
  </visual>
</link>
                                                                
        


      <joint name='link_JOINT_0' type='revolute'>
        <parent>front_swivel_link</parent>
        <child>front_axle_link</child>
        <pose>0 0 0 0 -0 0</pose>
        <axis>
          <xyz>1 0 0</xyz>
          <dynamics>
            <spring_reference>0</spring_reference>
            <spring_stiffness>0</spring_stiffness>
            <damping>0.5</damping>
          </dynamics>
        </axis>
        <physics>
          <ode>
            <limit>
      <cfm>1e-5</cfm>
      <erp>0.8</erp>
    </limit>
    <suspension>
      <cfm>1e-5</cfm>
      <erp>0.8</erp>
    </suspension>
          </ode>
        </physics>
      </joint>

      <joint name='swivel_JOINT_0' type='revolute'>
  <parent>base_link</parent>
  <child>front_swivel_link</child>
  <pose>0 0 0 0 0 0</pose>
  <axis>
    <xyz>0 0 1</xyz> <!-- Swivel axis (Y-axis) -->
    <dynamics>
      <spring_reference>0</spring_reference>
      <spring_stiffness>0</spring_stiffness> <!-- Gentle spring for swiveling -->
      <damping>5</damping>
    </dynamics>
    <limit>
      <lower>-0.05</lower> <!-- Swivel range in radians -->
      <upper>0.05</upper>
      <effort>2.0</effort>
      <velocity>0.5</velocity>
    </limit>
  </axis>
  <physics>
    <ode>
      <limit>
        <cfm>1e-4</cfm>
        <erp>0.7</erp>
      </limit>
    </ode>
  </physics>
</joint>


<joint name='swivel_JOINT_1' type='revolute'>
  <parent>base_link</parent>
  <child>back_swivel_link</child>
  <pose>0 0 0 0 0 0</pose>
  <axis>
    <xyz>0 0 1</xyz> <!-- Swivel axis (Y-axis) -->
    <dynamics>
      <spring_reference>0</spring_reference>
      <spring_stiffness>0</spring_stiffness> <!-- Gentle spring for swiveling -->
      <damping>5</damping>
    </dynamics>
    <limit>
      <lower>-0.05</lower> <!-- Swivel range in radians -->
      <upper>0.05</upper>
      <effort>2.0</effort>
      <velocity>0.5</velocity>
    </limit>
  </axis>
  <physics>
    <ode>
      <limit>
        <cfm>1e-4</cfm>
        <erp>0.7</erp>
      </limit>
    </ode>
  </physics>
</joint>

      <joint name='link_JOINT_1' type='revolute'>
        <parent>back_swivel_link</parent>
        <child>back_axle_link</child>
        <pose>0 0 0 0 -0 0</pose>
        <axis>
          <xyz>1 0 0</xyz>
          <dynamics>
            <spring_reference>0</spring_reference>
            <spring_stiffness>0</spring_stiffness>
            <damping>0.5</damping>
          </dynamics>
        </axis>
        <physics>
          <ode>
            <limit>
      <cfm>1e-5</cfm>
      <erp>0.8</erp>
    </limit>
    <suspension>
      <cfm>1e-5</cfm>
      <erp>0.8</erp>
    </suspension>
          </ode>
        </physics>
      </joint>

    <plugin name='amp_joint_state' filename='libgazebo_ros_joint_state_publisher.so'>
      <ros>
        <remapping>~/out:=joint_states</remapping>
      </ros>
      <update_rate>30</update_rate>
      <joint_name>link_JOINT_0</joint_name>
      <joint_name>link_JOINT_1</joint_name>
    </plugin>

    <plugin name="amp_diff_drive" filename="libgazebo_ros_diff_drive.so">

      <ros>
        <namespace>/tb3</namespace>
      </ros>

      <update_rate>30</update_rate>

      <!-- wheels -->
      <left_joint>link_JOINT_0</left_joint>
      <right_joint>link_JOINT_1</right_joint>

      <!-- kinematics -->
      <wheel_separation>1.5</wheel_separation>
      <wheel_diameter>0.3</wheel_diameter>

      <!-- limits -->
      <max_wheel_torque>200</max_wheel_torque>
      <max_wheel_acceleration>10.0</max_wheel_acceleration>

      <command_topic>cmd_vel</command_topic>

      <!-- output -->
      <publish_odom>true</publish_odom>
      <publish_odom_tf>true</publish_odom_tf>
      <publish_wheel_tf>false</publish_wheel_tf>

      <odometry_topic>odom</odometry_topic>
      <odometry_frame>odom</odometry_frame>
      <robot_base_frame>base_link</robot_base_frame>

    </plugin>


   


      <static>false</static>
      <!---<allow_auto_disable>1</allow_auto_disable> -->
    </model>
</sdf>

